Exception in thread Thread-1:
Traceback (most recent call last):
  File "/usr/lib/python3.8/threading.py", line 932, in _bootstrap_inner
    self.run()
  File "/usr/lib/python3.8/threading.py", line 870, in run
    self._target(*self._args, **self._kwargs)
  File "/home/fpmk/research/synthesis/paynt/synthesizer/synthesizer_pomdp.py", line 187, in strategy_iterative_storm
    assignment = self.synthesize(family, subfamilies=subfamilies, main_family=main_family)
  File "/home/fpmk/research/synthesis/paynt/synthesizer/synthesizer_pomdp.py", line 105, in synthesize
    assignment = synthesizer.synthesize(family, keep_optimum=True, print_stats=print_stats)
  File "/home/fpmk/research/synthesis/paynt/synthesizer/synthesizer.py", line 136, in synthesize
    assignment = self.synthesize_one(family)
  File "/home/fpmk/research/synthesis/paynt/synthesizer/synthesizer_ar_storm.py", line 137, in synthesize_one
    self.storm_control.parse_paynt_result(self.quotient)
  File "/home/fpmk/research/synthesis/paynt/quotient/storm_pomdp_control.py", line 652, in parse_paynt_result
    observation = self.quotient.observation_labels.index(obs)
ValueError: '0' is not in list
